<?xml version="1.0" ?>
<!-- =================================================================================== -->
<!-- |    This document was autogenerated by xacro from urdf/ur10_robot.urdf.xacro     | -->
<!-- |    EDITING THIS FILE BY HAND IS NOT RECOMMENDED                                 | -->
<!-- =================================================================================== -->
<robot name="ur10" xmlns:xacro="http://www.ros.org/wiki/xacro">
  <!-- common stuff -->
  <!-- ur10 -->
  <!-- arm -->
  <link name="base_link">
    <visual>
      <geometry>
        <mesh filename="./meshes/visual/base.dae"/>
      </geometry>
    </visual>
    <collision>
      <geometry>
        <mesh filename="./meshes/collision/base.stl"/>
      </geometry>
    </collision>
    <inertial>
      <mass value="4.0"/>
      <origin rpy="0 0 0" xyz="0.0 0.0 -1.5"/>
      <inertia ixx="0.0061063308908" ixy="0.0" ixz="0.0" iyy="0.0061063308908" iyz="0.0" izz="0.01125"/>
    </inertial>
  </link>
  <joint name="shoulder_pan_joint" type="revolute">
    <parent link="base_link"/>
    <child link="shoulder_link"/>
    <origin rpy="0.0 0.0 0.0" xyz="0.0 0.0 0.1273"/>
    <axis xyz="0 0 1"/>
    <limit effort="330.0" lower="-6.2831853" upper="6.2831853" velocity="2.16"/>
    <dynamics damping="0.0" friction="0.0"/>
  </joint>
  <link name="shoulder_link">
    <visual>
      <geometry>
        <mesh filename="./meshes/visual/shoulder.dae"/>
      </geometry>
    </visual>
    <collision>
      <geometry>
        <mesh filename="./meshes/collision/shoulder.stl"/>
      </geometry>
    </collision>
    <inertial>
      <mass value="7.778"/>
      <origin rpy="0 0 0" xyz="0.0 0.0 0.0"/>
      <inertia ixx="0.0314743125769" ixy="0.0" ixz="0.0" iyy="0.0314743125769" iyz="0.0" izz="0.021875625"/>
    </inertial>
  </link>
  <joint name="shoulder_lift_joint" type="revolute">
    <parent link="shoulder_link"/>
    <child link="upper_arm_link"/>
    <origin rpy="0.0 1.570796325 0.0" xyz="0.0 0.220941 0.0"/>
    <axis xyz="0 1 0"/>
    <limit effort="330.0" lower="-6.2831853" upper="6.2831853" velocity="2.16"/>
    <dynamics damping="0.0" friction="0.0"/>
  </joint>
  <link name="upper_arm_link">
    <visual>
      <geometry>
        <mesh filename="./meshes/visual/upperarm.dae"/>
      </geometry>
    </visual>
    <collision>
      <geometry>
        <mesh filename="./meshes//collision/upperarm.stl"/>
      </geometry>
    </collision>
    <inertial>
      <mass value="12.93"/>
      <origin rpy="0 0 0" xyz="0.0 0.0 0.306"/>
      <inertia ixx="0.421753803798" ixy="0.0" ixz="0.0" iyy="0.421753803798" iyz="0.0" izz="0.036365625"/>
    </inertial>
  </link>
  <joint name="elbow_joint" type="revolute">
    <parent link="upper_arm_link"/>
    <child link="forearm_link"/>
    <origin rpy="0.0 0.0 0.0" xyz="0.0 -0.1719 0.612"/>
    <axis xyz="0 1 0"/>
    <limit effort="150.0" lower="-6.2831853" upper="6.2831853" velocity="3.15"/>
    <dynamics damping="0.0" friction="0.0"/>
  </joint>
  <link name="forearm_link">
    <visual>
      <geometry>
        <mesh filename="./meshes/visual/forearm.dae"/>
      </geometry>
    </visual>
    <collision>
      <geometry>
        <mesh filename="./meshes/collision/forearm.stl"/>
      </geometry>
    </collision>
    <inertial>
      <mass value="3.87"/>
      <origin rpy="0 0 0" xyz="0.0 0.0 0.28615"/>
      <inertia ixx="0.111069694097" ixy="0.0" ixz="0.0" iyy="0.111069694097" iyz="0.0" izz="0.010884375"/>
    </inertial>
  </link>
  <joint name="wrist_1_joint" type="revolute">
    <parent link="forearm_link"/>
    <child link="wrist_1_link"/>
    <origin rpy="0.0 1.570796325 0.0" xyz="0.0 0.0 0.5723"/>
    <axis xyz="0 1 0"/>
    <limit effort="54.0" lower="-6.2831853" upper="6.2831853" velocity="3.2"/>
    <dynamics damping="0.0" friction="0.0"/>
  </joint>
  <link name="wrist_1_link">
    <visual>
      <geometry>
        <mesh filename="./meshes/visual/wrist1.dae"/>
      </geometry>
    </visual>
    <collision>
      <geometry>
        <mesh filename="./meshes/collision/wrist1.stl"/>
      </geometry>
    </collision>
    <inertial>
      <mass value="1.96"/>
      <origin rpy="0 0 0" xyz="0.0 0.0 0.0"/>
      <inertia ixx="0.0051082479567" ixy="0.0" ixz="0.0" iyy="0.0051082479567" iyz="0.0" izz="0.0055125"/>
    </inertial>
  </link>



  <transmission name="shoulder_pan_trans">
    <type>transmission_interface/SimpleTransmission</type>
    <joint name="shoulder_pan_joint"/>
    <actuator name="shoulder_pan_motor">
      <hardwareInterface>EffortJointInterface</hardwareInterface>
      <mechanicalReduction>1</mechanicalReduction>
    </actuator>
  </transmission>
  <transmission name="shoulder_lift_trans">
    <type>transmission_interface/SimpleTransmission</type>
    <joint name="shoulder_lift_joint"/>
    <actuator name="shoulder_lift_motor">
      <hardwareInterface>EffortJointInterface</hardwareInterface>
      <mechanicalReduction>1</mechanicalReduction>
    </actuator>
  </transmission>
  <transmission name="elbow_trans">
    <type>transmission_interface/SimpleTransmission</type>
    <joint name="elbow_joint"/>
    <actuator name="elbow_motor">
      <hardwareInterface>EffortJointInterface</hardwareInterface>
      <mechanicalReduction>1</mechanicalReduction>
    </actuator>
  </transmission>
  <transmission name="wrist_1_trans">
    <type>transmission_interface/SimpleTransmission</type>
    <joint name="wrist_1_joint"/>
    <actuator name="wrist_1_motor">
      <hardwareInterface>EffortJointInterface</hardwareInterface>
      <mechanicalReduction>1</mechanicalReduction>
    </actuator>
  </transmission>
  <transmission name="wrist_2_trans">
    <type>transmission_interface/SimpleTransmission</type>
    <joint name="wrist_2_joint"/>
    <actuator name="wrist_2_motor">
      <hardwareInterface>EffortJointInterface</hardwareInterface>
      <mechanicalReduction>1</mechanicalReduction>
    </actuator>
  </transmission>
  <transmission name="wrist_3_trans">
    <type>transmission_interface/SimpleTransmission</type>
    <joint name="wrist_3_joint"/>
    <actuator name="wrist_3_motor">
      <hardwareInterface>EffortJointInterface</hardwareInterface>
      <mechanicalReduction>1</mechanicalReduction>
    </actuator>
  </transmission>

</robot>

